Workbook

Sheet Dashboard
A3: Row Labels | B3: Sum of Amount | C3: Budget | D3: Variance | E3: % of Budget
A4: Actuarial & Risk | B4: 22194.23 | C4: 22500 | D4: =B4-C4 -> -305.77 | E4: =ROUND(B4/C4*100,1) -> 98.6
A5: Claims | B5: 74054.58 | C5: 79000 | D5: =B5-C5 -> -4945.42 | E5: =ROUND(B5/C5*100,1) -> 93.7
A6: Customer Support | B6: 19374.32 | C6: 19850 | D6: =B6-C6 -> -475.68 | E6: =ROUND(B6/C6*100,1) -> 97.6
A7: Executive & Corporate | B7: 25941.69 | C7: 31500 | D7: =B7-C7 -> -5558.31 | E7: =ROUND(B7/C7*100,1) -> 82.4
A8: Finance | B8: 28021.39 | C8: 33000 | D8: =B8-C8 -> -4978.61 | E8: =ROUND(B8/C8*100,1) -> 84.9
A9: HR & Events | B9: 25822.34 | C9: 36500 | D9: =B9-C9 -> -10677.66 | E9: =ROUND(B9/C9*100,1) -> 70.7
A10: IT & Platform Engineering | B10: 19174.13 | C10: 16000 | D10: =B10-C10 -> 3174.13 | E10: =ROUND(B10/C10*100,1) -> 119.8
A11: Sales & Marketing | B11: 307950.11 | C11: 196500 | D11: =B11-C11 -> 111450.11 | E11: =ROUND(B11/C11*100,1) -> 156.7
A12: Underwriting | B12: 67113.87 | C12: 75000 | D12: =B12-C12 -> -7886.13 | E12: =ROUND(B12/C12*100,1) -> 89.5
A13: Grand Total | B13: 589646.66
A20: Row Labels | B20: Actual Spend | C20: Budget
A21: Actuarial & Risk | B21: 22194.23 | C21: 22500
A22: Claims | B22: 74054.58 | C22: 79000
A23: Customer Support | B23: 19374.32 | C23: 19850
A24: Executive & Corporate | B24: 25941.69 | C24: 31500
A25: Finance | B25: 28021.39 | C25: 33000
A26: HR & Events | B26: 25822.34 | C26: 36500
A27: IT & Platform Engineering | B27: 19174.13 | C27: 16000
A28: Sales & Marketing | B28: 307950.11 | C28: 196500
A29: Underwriting | B29: 67113.87 | C29: 75000

Sheet Transactions
A1: ExpID | B1: EmpID | C1: TransactionID | D1: ExpenseDate | E1: SubmissionDate | F1: Merchant | G1: MCC | H1: Category_SelfReported | I1: Amount | J1: PaymentMethod | K1: ReasonIfPersonal | L1: ReceiptAttached | M1: FinalCategory | N1: CategoryCheck | O1: Department
A2: EXP100000 | B2: E046 | C2: AX796358997 | D2: 46023 | E2: 46023 | F2: SOUTHWEST AIR 5261823 | G2: 4511 | H2: Travel | I2: 421.91 | J2: Corporate Amex | L2: Y | M2: =INDEX(MCC_Lookup!$B$2:$B$12,MATCH(G2,MCC_Lookup!$A$2:$A$12,0)) -> Travel | N2: =IF(TRIM(H2)="","BLANK",IF(PROPER(TRIM(H2))=TRIM(M2),"MATCH","MISMATCH")) -> MATCH | O2: =INDEX([1]Employee!$C$2:$C$276,MATCH(B2,[1]Employee!$A$2:$A$276,0)) -> Sales & Marketing
A3: EXP100001 | B3: E034 | C3: AX702910218 | D3: 46024 | E3: 46024 | F3: SQ *JOES COFFEE | G3: 5812 | H3: Meals | I3: 10.88 | J3: Corporate Amex | L3: Y | M3: =INDEX(MCC_Lookup!$B$2:$B$12,MATCH(G3,MCC_Lookup!$A$2:$A$12,0)) -> Meals | N3: =IF(TRIM(H3)="","BLANK",IF(PROPER(TRIM(H3))=TRIM(M3),"MATCH","MISMATCH")) -> MATCH | O3: =INDEX([1]Employee!$C$2:$C$276,MATCH(B3,[1]Employee!$A$2:$A$276,0)) -> Sales & Marketing
A4: EXP100002 | B4: E245 | C4: ax306239836 | D4: 46024 | E4: 46024 | F4: MARRIOTT #4471 | G4: 7011 | H4: Lodging | I4: 147.64 | J4: Corporate Amex | L4: N | M4: =INDEX(MCC_Lookup!$B$2:$B$12,MATCH(G4,MCC_Lookup!$A$2:$A$12,0)) -> Lodging | N4: =IF(TRIM(H4)="","BLANK",IF(PROPER(TRIM(H4))=TRIM(M4),"MATCH","MISMATCH")) -> MATCH | O4: =INDEX([1]Employee!$C$2:$C$276,MATCH(B4,[1]Employee!$A$2:$A$276,0)) -> IT & Platform Engineering
A5: EXP100003 | B5: E003 | C5: AX-471430209 | D5: 46023 | E5: 46024 | F5: AMC THEATRES 0021 | G5: 7832 | H5: Entertainment | I5: 23.5 | J5: Corporate Amex | L5: N | M5: =INDEX(MCC_Lookup!$B$2:$B$12,MATCH(G5,MCC_Lookup!$A$2:$A$12,0)) -> Entertainment | N5: =IF(TRIM(H5)="","BLANK",IF(PROPER(TRIM(H5))=TRIM(M5),"MATCH","MISMATCH")) -> MATCH | O5: =INDEX([1]Employee!$C$2:$C$276,MATCH(B5,[1]Employee!$A$2:$A$276,0)) -> Sales & Marketing
A6: EXP100004 | B6: E060 | C6: AX277703916 | D6: 46024 | E6: 46024 | F6: DELTA AIR 00623891045 | G6: 4511 | H6: travel | I6: 477.78 | J6: Corporate Amex | L6: N | M6: =INDEX(MCC_Lookup!$B$2:$B$12,MATCH(G6,MCC_Lookup!$A$2:$A$12,0)) -> Travel | N6: =IF(TRIM(H6)="","BLANK",IF(PROPER(TRIM(H6))=TRIM(M6),"MATCH","MISMATCH")) -> MATCH | O6: =INDEX([1]Employee!$C$2:$C$276,MATCH(B6,[1]Employee!$A$2:$A$276,0)) -> Sales & Marketing
A7: EXP100005 | B7: E051 | C7: AX170388883 | D7: 46023 | E7: 46024 | F7: ADOBE *CREATIVE CLOUD | G7: 5734 | H7: Meals | I7: 46.08 | J7: Corporate Amex | L7: Y | M7: =INDEX(MCC_Lookup!$B$2:$B$12,MATCH(G7,MCC_Lookup!$A$2:$A$12,0)) -> Software | N7: =IF(TRIM(H7)="","BLANK",IF(PROPER(TRIM(H7))=TRIM(M7),"MATCH","MISMATCH")) -> MISMATCH | O7: =INDEX([1]Employee!$C$2:$C$276,MATCH(B7,[1]Employee!$A$2:$A$276,0)) -> Sales & Marketing
A8: EXP100006 | B8: E005 | C8: AX256030931 | D8: 46024 | E8: 46024 | F8: TOTAL PARTY RENTAL | G8: 7999 | H8: Events | I8: 215.53 | J8: Corporate Amex | L8: Y | M8: =INDEX(MCC_Lookup!$B$2:$B$12,MATCH(G8,MCC_Lookup!$A$2:$A$12,0)) -> Events | N8: =IF(TRIM(H8)="","BLANK",IF(PROPER(TRIM(H8))=TRIM(M8),"MATCH","MISMATCH")) -> MATCH | O8: =INDEX([1]Employee!$C$2:$C$276,MATCH(B8,[1]Employee!$A$2:$A$276,0)) -> Sales & Marketing
A9: EXP100007 | B9: E057 | C9: AX-738070828 | D9: 46025 | E9: 46025 | F9: LYFT RIDE THU | G9: 4121 | H9: Transportation | I9: 51.17 | J9: Corporate Amex | L9: Y | M9: =INDEX(MCC_Lookup!$B$2:$B$12,MATCH(G9,MCC_Lookup!$A$2:$A$12,0)) -> Transportation | N9: =IF(TRIM(H9)="","BLANK",IF(PROPER(TRIM(H9))=TRIM(M9),"MATCH","MISMATCH")) -> MATCH | O9: =INDEX([1]Employee!$C$2:$C$276,MATCH(B9,[1]Employee!$A$2:$A$276,0)) -> Sales & Marketing
A10: EXP100008 | B10: E029 | D10: 46023 | E10: 46025 | F10: UBER TRIP HELP.UBER | G10: 4121 | H10: Transportation | I10: 28.57 | J10: Corporate Amex | L10: Y | M10: =INDEX(MCC_Lookup!$B$2:$B$12,MATCH(G10,MCC_Lookup!$A$2:$A$12,0)) -> Transportation | N10: =IF(TRIM(H10)="","BLANK",IF(PROPER(TRIM(H10))=TRIM(M10),"MATCH","MISMATCH")) -> MATCH | O10: =INDEX([1]Employee!$C$2:$C$276,MATCH(B10,[1]Employee!$A$2:$A$276,0)) -> Sales & Marketing
A11: EXP100009 | B11: E109 | C11: AX455963115 | D11: 46025 | E11: 46025 | F11: BRANDWATCH LTD | G11: 5734 | H11: Software | I11: 583.36 | J11: Corporate Amex | L11: Y | M11: =INDEX(MCC_Lookup!$B$2:$B$12,MATCH(G11,MCC_Lookup!$A$2:$A$12,0)) -> Software | N11: =IF(TRIM(H11)="","BLANK",IF(PROPER(TRIM(H11))=TRIM(M11),"MATCH","MISMATCH")) -> MATCH | O11: =INDEX([1]Employee!$C$2:$C$276,MATCH(B11,[1]Employee!$A$2:$A$276,0)) -> Underwriting
A12: EXP100010 | B12: E060 | C12: AX-880479202 | D12: 46024 | E12: 46025 | F12: SPROUT SOCIAL | G12: 5734 | H12: Software | I12: 241.22 | J12: Corporate Amex | L12: Y | M12: =INDEX(MCC_Lookup!$B$2:$B$12,MATCH(G12,MCC_Lookup!$A$2:$A$12,0)) -> Software | N12: =IF(TRIM(H12)="","BLANK",IF(PROPER(TRIM(H12))=TRIM(M12),"MATCH","MISMATCH")) -> MATCH | O12: =INDEX([1]Employee!$C$2:$C$276,MATCH(B12,[1]Employee!$A$2:$A$276,0)) -> Sales & Marketing
A13: EXP100011 | B13: E015 | C13: AX995549228 | D13: 46026 | E13: 46026 | F13: PANERA BREAD #0231 | G13: 5812 | H13: Meals | I13: 17.92 | J13: Corporate Amex | L13: Y | M13: =INDEX(MCC_Lookup!$B$2:$B$12,MATCH(G13,MCC_Lookup!$A$2:$A$12,0)) -> Meals | N13: =IF(TRIM(H13)="","BLANK",IF(PROPER(TRIM(H13))=TRIM(M13),"MATCH","MISMATCH")) -> MATCH | O13: =INDEX([1]Employee!$C$2:$C$276,MATCH(B13,[1]Employee!$A$2:$A$276,0)) -> Sales & Marketing
A14: EXP100012 | B14: E034 | C14: AX726487324 | D14: 46024 | E14: 46026 | F14: ADOBE *CREATIVE CLOUD | G14: 5734 | H14: Software | I14: 88.89 | J14: Corporate Amex | L14: Y | M14: =INDEX(MCC_Lookup!$B$2:$B$12,MATCH(G14,MCC_Lookup!$A$2:$A$12,0)) -> Software | N14: =IF(TRIM(H14)="","BLANK",IF(PROPER(TRIM(H14))=TRIM(M14),"MATCH","MISMATCH")) -> MATCH | O14: =INDEX([1]Employee!$C$2:$C$276,MATCH(B14,[1]Employee!$A$2:$A$276,0)) -> Sales & Marketing
A15: EXP100013 | B15: E262 | C15: ax225779385 | D15: 46024 | E15: 46026 | F15: AMC THEATRES 0021 | G15: 7832 | H15: Entertainment | I15: 23.69 | J15: Corporate Amex | L15: Y | M15: =INDEX(MCC_Lookup!$B$2:$B$12,MATCH(G15,MCC_Lookup!$A$2:$A$12,0)) -> Entertainment | N15: =IF(TRIM(H15)="","BLANK",IF(PROPER(TRIM(H15))=TRIM(M15),"MATCH","MISMATCH")) -> MATCH | O15: =INDEX([1]Employee!$C$2:$C$276,MATCH(B15,[1]Employee!$A$2:$A$276,0)) -> HR & Events
A16: EXP100014 | B16: E039 | C16: AX484370441 | D16: 46025 | E16: 46026 | F16: STAPLES #0231 | G16: 5943 | H16: Travel | I16: 111.81 | J16: Corporate Amex | L16: Y | M16: =INDEX(MCC_Lookup!$B$2:$B$12,MATCH(G16,MCC_Lookup!$A$2:$A$12,0)) -> Office Supplies | N16: =IF(TRIM(H16)="","BLANK",IF(PROPER(TRIM(H16))=TRIM(M16),"MATCH","MISMATCH")) -> MISMATCH | O16: =INDEX([1]Employee!$C$2:$C$276,MATCH(B16,[1]Employee!$A$2:$A$276,0)) -> Sales & Marketing
A17: EXP100015 | B17: E234 | D17: 46025 | E17: 46026 | F17: HILTON GARDEN INN 2231 | G17: 7011 | H17: Lodging | I17: 132.89 | J17: Corporate Amex | L17: Y | M17: =INDEX(MCC_Lookup!$B$2:$B$12,MATCH(G17,MCC_Lookup!$A$2:$A$12,0)) -> Lodging | N17: =IF(TRIM(H17)="","BLANK",IF(PROPER(TRIM(H17))=TRIM(M17),"MATCH","MISMATCH")) -> MATCH | O17: =INDEX([1]Employee!$C$2:$C$276,MATCH(B17,[1]Employee!$A$2:$A$276,0)) -> IT & Platform Engineering
A18: EXP100016 | B18: E040 | C18: AX 549252229 | D18: 46023 | E18: 46026 | F18: OLIVE GARDEN 00456 | G18: 5812 | H18: Meals | I18: 26.64 | J18: Corporate Amex | L18: Y | M18: =INDEX(MCC_Lookup!$B$2:$B$12,MATCH(G18,MCC_Lookup!$A$2:$A$12,0)) -> Meals | N18: =IF(TRIM(H18)="","BLANK",IF(PROPER(TRIM(H18))=TRIM(M18),"MATCH","MISMATCH")) -> MATCH | O18: =INDEX([1]Employee!$C$2:$C$276,MATCH(B18,[1]Employee!$A$2:$A$276,0)) -> Sales & Marketing
A19: EXP100017 | B19: E103 | C19: AX726344621 | D19: 46024 | E19: 46026 | F19: UBER TRIP HELP.UBER | G19: 4121 | H19: Transportation | I19: 35.63 | J19: Corporate Amex | L19: Y | M19: =INDEX(MCC_Lookup!$B$2:$B$12,MATCH(G19,MCC_Lookup!$A$2:$A$12,0)) -> Transportation | N19: =IF(TRIM(H19)="","BLANK",IF(PROPER(TRIM(H19))=TRIM(M19),"MATCH","MISMATCH")) -> MATCH | O19: =INDEX([1]Employee!$C$2:$C$276,MATCH(B19,[1]Employee!$A$2:$A$276,0)) -> Underwriting
A20: EXP100018 | B20: E011 | C20: AX-613118642 | D20: 46023 | E20: 46026 | F20: HOOTSUITE INC | G20: 5734 | H20: Software | I20: 69.13 | J20: Corporate Amex | L20: Y | M20: =INDEX(MCC_Lookup!$B$2:$B$12,MATCH(G20,MCC_Lookup!$A$2:$A$12,0)) -> Software | N20: =IF(TRIM(H20)="","BLANK",IF(PROPER(TRIM(H20))=TRIM(M20),"MATCH","MISMATCH")) -> MATCH | O20: =INDEX([1]Employee!$C$2:$C$276,MATCH(B20,[1]Employee!$A$2:$A$276,0)) -> Sales & Marketing
A21: EXP100019 | B21: E069 | D21: 46025 | E21: 46026 | F21: EVENTBRITE | G21: 7999 | H21: Events | I21: 118.6 | J21: Corporate Amex | L21: Y | M21: =INDEX(MCC_Lookup!$B$2:$B$12,MATCH(G21,MCC_Lookup!$A$2:$A$12,0)) -> Events | N21: =IF(TRIM(H21)="","BLANK",IF(PROPER(TRIM(H21))=TRIM(M21),"MATCH","MISMATCH")) -> MATCH | O21: =INDEX([1]Employee!$C$2:$C$276,MATCH(B21,[1]Employee!$A$2:$A$276,0)) -> Sales & Marketing
A22: EXP100020 | B22: E051 | D22: 46027 | E22: 46027 | F22: DELTA AIR 00623891045 | G22: 4511 | H22: Travel | I22: 533.91 | J22: Personal (Reimbursement) | K22: International merchant - Amex not accepted | L22: Y | M22: =INDEX(MCC_Lookup!$B$2:$B$12,MATCH(G22,MCC_Lookup!$A$2:$A$12,0)) -> Travel | N22: =IF(TRIM(H22)="","BLANK",IF(PROPER(TRIM(H22))=TRIM(M22),"MATCH","MISMATCH")) -> MATCH | O22: =INDEX([1]Employee!$C$2:$C$276,MATCH(B22,[1]Employee!$A$2:$A$276,0)) -> Sales & Marketing
A23: EXP100021 | B23: E088 | C23: AX 440929016 | D23: 46023 | E23: 46027 | F23: CHIPOTLE 2214 | G23: 5812 | H23: Meals | I23: 20.36 | J23: Corporate Amex | L23: Y | M23: =INDEX(MCC_Lookup!$B$2:$B$12,MATCH(G23,MCC_Lookup!$A$2:$A$12,0)) -> Meals | N23: =IF(TRIM(H23)="","BLANK",IF(PROPER(TRIM(H23))=TRIM(M23),"MATCH","MISMATCH")) -> MATCH | O23: =INDEX([1]Employee!$C$2:$C$276,MATCH(B23,[1]Employee!$A$2:$A$276,0)) -> Underwriting
A24: EXP100022 | B24: E079 | C24: AX-418999135 | D24: 46024 | E24: 46027 | F24: AMAZON MKTPLACE PMTS | G24: 5942 | H24: Office Supplies | I24: 375.81 | J24: Corporate Amex | L24: Y | M24: =INDEX(MCC_Lookup!$B$2:$B$12,MATCH(G24,MCC_Lookup!$A$2:$A$12,0)) -> Office Supplies | N24: =IF(TRIM(H24)="","BLANK",IF(PROPER(TRIM(H24))=TRIM(M24),"MATCH","MISMATCH")) -> MATCH | O24: =INDEX([1]Employee!$C$2:$C$276,MATCH(B24,[1]Employee!$A$2:$A$276,0)) -> Underwriting
A25: EXP100023 | B25: E064 | C25: AX937168052 | D25: 46027 | E25: 46027 | F25: TOPGOLF #442 | G25: 7997 | H25: Entertainment | I25: 154.45 | J25: Corporate Amex | L25: Y | M25: =INDEX(MCC_Lookup!$B$2:$B$12,MATCH(G25,MCC_Lookup!$A$2:$A$12,0)) -> Entertainment | N25: =IF(TRIM(H25)="","BLANK",IF(PROPER(TRIM(H25))=TRIM(M25),"MATCH","MISMATCH")) -> MATCH | O25: =INDEX([1]Employee!$C$2:$C$276,MATCH(B25,[1]Employee!$A$2:$A$276,0)) -> Sales & Marketing
A26: EXP100025 | B26: E228 | D26: 46024 | E26: 46027 | F26: TOTAL PARTY RENTAL | G26: 7999 | H26: Events | I26: 216.9 | J26: Personal (Reimbursement) | K26: Card not yet issued | L26: N | M26: =INDEX(MCC_Lookup!$B$2:$B$12,MATCH(G26,MCC_Lookup!$A$2:$A$12,0)) -> Events | N26: =IF(TRIM(H26)="","BLANK",IF(PROPER(TRIM(H26))=TRIM(M26),"MATCH","MISMATCH")) -> MATCH | O26: =INDEX([1]Employee!$C$2:$C$276,MATCH(B26,[1]Employee!$A$2:$A$276,0)) -> Actuarial & Risk
A27: EXP100026 | B27: E054 | C27: AX217887407 | D27: 46024 | E27: 46027 | F27: AMAZON MKTPLACE PMTS | G27: 5942 | H27: OFFICE SUPPLIES | I27: 232.35 | J27: Corporate Amex | L27: N | M27: =INDEX(MCC_Lookup!$B$2:$B$12,MATCH(G27,MCC_Lookup!$A$2:$A$12,0)) -> Office Supplies | N27: =IF(TRIM(H27)="","BLANK",IF(PROPER(TRIM(H27))=TRIM(M27),"MATCH","MISMATCH")) -> MATCH | O27: =INDEX([1]Employee!$C$2:$C$276,MATCH(B27,[1]Employee!$A$2:$A$276,0)) -> Sales & Marketing
A28: EXP100027 | B28: E190 | C28: AX 583718208 | D28: 46024 | E28: 46027 | F28: ADOBE *CREATIVE CLOUD | G28: 5734 | H28: Software | I28: 34.44 | J28: Corporate Amex | L28: Y | M28: =INDEX(MCC_Lookup!$B$2:$B$12,MATCH(G28,MCC_Lookup!$A$2:$A$12,0)) -> Software | N28: =IF(TRIM(H28)="","BLANK",IF(PROPER(TRIM(H28))=TRIM(M28),"MATCH","MISMATCH")) -> MATCH | O28: =INDEX([1]Employee!$C$2:$C$276,MATCH(B28,[1]Employee!$A$2:$A$276,0)) -> Finance
A29: EXP100028 | B29: E019 | C29: ax550840415 | D29: 46026 | E29: 46027 | F29: CHIPOTLE 2214 | G29: 5812 | H29: MEALS | I29: 11.88 | J29: Corporate Amex | L29: Y | M29: =INDEX(MCC_Lookup!$B$2:$B$12,MATCH(G29,MCC_Lookup!$A$2:$A$12,0)) -> Meals | N29: =IF(TRIM(H29)="","BLANK",IF(PROPER(TRIM(H29))=TRIM(M29),"MATCH","MISMATCH")) -> MATCH | O29: =INDEX([1]Employee!$C$2:$C$276,MATCH(B29,[1]Employee!$A$2:$A$276,0)) -> Sales & Marketing
A30: EXP100029 | B30: E185 | D30: 46023 | E30: 46027 | F30: MARRIOTT #4471 | G30: 7011 | H30: Lodging | I30: 240.32 | J30: Corporate Amex | L30: Y | M30: =INDEX(MCC_Lookup!$B$2:$B$12,MATCH(G30,MCC_Lookup!$A$2:$A$12,0)) -> Lodging | N30: =IF(TRIM(H30)="","BLANK",IF(PROPER(TRIM(H30))=TRIM(M30),"MATCH","MISMATCH")) -> MATCH | O30: =INDEX([1]Employee!$C$2:$C$276,MATCH(B30,[1]Employee!$A$2:$A$276,0)) -> Finance
A31: EXP100030 | B31: E005 | C31: ax609743196 | D31: 46027 | E31: 46027 | F31: SPROUT SOCIAL | G31: 5734 | H31: Software | I31: 111.1 | J31: Corporate Amex | L31: Y | M31: =INDEX(MCC_Lookup!$B$2:$B$12,MATCH(G31,MCC_Lookup!$A$2:$A$12,0)) -> Software | N31: =IF(TRIM(H31)="","BLANK",IF(PROPER(TRIM(H31))=TRIM(M31),"MATCH","MISMATCH")) -> MATCH | O31: =INDEX([1]Employee!$C$2:$C$276,MATCH(B31,[1]Employee!$A$2:$A$276,0)) -> Sales & Marketing
A32: EXP100031 | B32: E069 | C32: AX-722348588 | D32: 46023 | E32: 46027 | F32: HOOTSUITE INC | G32: 5734 | H32: Software | I32: 167.3 | J32: Corporate Amex | L32: Y | M32: =INDEX(MCC_Lookup!$B$2:$B$12,MATCH(G32,MCC_Lookup!$A$2:$A$12,0)) -> Software | N32: =IF(TRIM(H32)="","BLANK",IF(PROPER(TRIM(H32))=TRIM(M32),"MATCH","MISMATCH")) -> MATCH | O32: =INDEX([1]Employee!$C$2:$C$276,MATCH(B32,[1]Employee!$A$2:$A$276,0)) -> Sales & Marketing
A33: EXP100032 | B33: E265 | C33: ax928291530 | D33: 46027 | E33: 46027 | F33: AMC THEATRES 0021 | G33: 7832 | H33: Entertainment | I33: 35.86 | J33: Corporate Amex | L33: Y | M33: =INDEX(MCC_Lookup!$B$2:$B$12,MATCH(G33,MCC_Lookup!$A$2:$A$12,0)) -> Entertainment | N33: =IF(TRIM(H33)="","BLANK",IF(PROPER(TRIM(H33))=TRIM(M33),"MATCH","MISMATCH")) -> MATCH | O33: =INDEX([1]Employee!$C$2:$C$276,MATCH(B33,[1]Employee!$A$2:$A$276,0)) -> HR & Events
A34: EXP100033 | B34: E038 | C34: ax110083781 | D34: 46024 | E34: 46027 | F34: DELTA AIR 00623891045 | G34: 4511 | H34: Travel | I34: 592.92 | J34: Corporate Amex | L34: N | M34: =INDEX(MCC_Lookup!$B$2:$B$12,MATCH(G34,MCC_Lookup!$A$2:$A$12,0)) -> Travel | N34: =IF(TRIM(H34)="","BLANK",IF(PROPER(TRIM(H34))=TRIM(M34),"MATCH","MISMATCH")) -> MATCH | O34: =INDEX([1]Employee!$C$2:$C$276,MATCH(B34,[1]Employee!$A$2:$A$276,0)) -> Sales & Marketing
A35: EXP100034 | B35: E027 | C35: AX409802117 | D35: 46025 | E35: 46028 | F35: SQ *JOES COFFEE | G35: 5812 | H35: meals | I35: 15.94 | J35: Corporate Amex | L35: Y | M35: =INDEX(MCC_Lookup!$B$2:$B$12,MATCH(G35,MCC_Lookup!$A$2:$A$12,0)) -> Meals | N35: =IF(TRIM(H35)="","BLANK",IF(PROPER(TRIM(H35))=TRIM(M35),"MATCH","MISMATCH")) -> MATCH | O35: =INDEX([1]Employee!$C$2:$C$276,MATCH(B35,[1]Employee!$A$2:$A$276,0)) -> Sales & Marketing
A36: EXP100035 | B36: E033 | C36: ax164470418 | D36: 46025 | E36: 46028 | F36: MARRIOTT #4471 | G36: 7011 | H36: Lodging | I36: 291.45 | J36: Corporate Amex | L36: N | M36: =INDEX(MCC_Lookup!$B$2:$B$12,MATCH(G36,MCC_Lookup!$A$2:$A$12,0)) -> Lodging | N36: =IF(TRIM(H36)="","BLANK",IF(PROPER(TRIM(H36))=TRIM(M36),"MATCH","MISMATCH")) -> MATCH | O36: =INDEX([1]Employee!$C$2:$C$276,MATCH(B36,[1]Employee!$A$2:$A$276,0)) -> Sales & Marketing
A37: EXP100036 | B37: E218 | D37: 46024 | E37: 46028 | F37: HYATT REGENCY BOS | G37: 7011 | H37: Lodging | I37: 388.47 | J37: Personal (Reimbursement) | K37: Amex declined - vendor doesn't accept Amex | L37: Y | M37: =INDEX(MCC_Lookup!$B$2:$B$12,MATCH(G37,MCC_Lookup!$A$2:$A$12,0)) -> Lodging | N37: =IF(TRIM(H37)="","BLANK",IF(PROPER(TRIM(H37))=TRIM(M37),"MATCH","MISMATCH")) -> MATCH | O37: =INDEX([1]Employee!$C$2:$C$276,MATCH(B37,[1]Employee!$A$2:$A$276,0)) -> Actuarial & Risk
A38: EXP100038 | B38: E171 | C38: AX 167694832 | D38: 46028 | E38: 46028 | F38: STAPLES #0231 | G38: 5943 | H38: Office Supplies | I38: 67.55 | J38: Corporate Amex | L38: Y | M38: =INDEX(MCC_Lookup!$B$2:$B$12,MATCH(G38,MCC_Lookup!$A$2:$A$12,0)) -> Office Supplies | N38: =IF(TRIM(H38)="","BLANK",IF(PROPER(TRIM(H38))=TRIM(M38),"MATCH","MISMATCH")) -> MATCH | O38: =INDEX([1]Employee!$C$2:$C$276,MATCH(B38,[1]Employee!$A$2:$A$276,0)) -> Customer Support
A39: EXP100039 | B39: E212 | C39: AX 928412993 | D39: 46023 | E39: 46028 | F39: EVENTBRITE | G39: 7999 | H39: Events | I39: 96.39 | J39: Corporate Amex | L39: Y | M39: =INDEX(MCC_Lookup!$B$2:$B$12,MATCH(G39,MCC_Lookup!$A$2:$A$12,0)) -> Events | N39: =IF(TRIM(H39)="","BLANK",IF(PROPER(TRIM(H39))=TRIM(M39),"MATCH","MISMATCH")) -> MATCH | O39: =INDEX([1]Employee!$C$2:$C$276,MATCH(B39,[1]Employee!$A$2:$A$276,0)) -> Actuarial & Risk
A40: EXP100040 | B40: E046 | C40: AX638500943 | D40: 46028 | E40: 46028 | F40: TOTAL PARTY RENTAL | G40: 7999 | H40: Events | I40: 448.47 | J40: Corporate Amex | L40: Y | M40: =INDEX(MCC_Lookup!$B$2:$B$12,MATCH(G40,MCC_Lookup!$A$2:$A$12,0)) -> Events | N40: =IF(TRIM(H40)="","BLANK",IF(PROPER(TRIM(H40))=TRIM(M40),"MATCH","MISMATCH")) -> MATCH | O40: =INDEX([1]Employee!$C$2:$C$276,MATCH(B40,[1]Employee!$A$2:$A$276,0)) -> Sales & Marketing
...

Sheet Removed_Duplicates
A1: ExpID | B1: DuplicateOfExpID | C1: EmpID | D1: TransactionID | E1: ExpenseDate | F1: SubmissionDate | G1: Merchant | H1: MCC | I1: Category_SelfReported | J1: Amount | K1: PaymentMethod | L1: ReasonIfPersonal | M1: ReceiptAttached | N1: FinalCategory | O1: CategoryCheck
A2: EXP100024 | B2: EXP100023 | C2: E064 | D2: AX937168052 | E2: 2026-01-05 | F2: 2026-01-05 | G2: TOPGOLF #442 | H2: 7997 | I2: Entertainment | J2: 154.45 | K2: Corporate Amex | M2: Y | N2: Entertainment | O2: MATCH
A3: EXP100037 | B3: EXP100036 | C3: E218 | E3: 2026-01-02 | F3: 2026-01-06 | G3: HYATT REGENCY BOS | H3: 7011 | I3: Lodging | J3: 388.47 | K3: Personal (Reimbursement) | L3: Amex declined - vendor doesn't accept Amex | M3: Y | N3: Lodging | O3: MATCH
A4: EXP100156 | B4: EXP100155 | C4: E017 | D4: ax205858521 | E4: 2026-01-09 | F4: 2026-01-13 | G4: OLIVE GARDEN 00456 | H4: 5812 | I4: Meals | J4: 28.59 | K4: Corporate Amex | M4: Y | N4: Meals | O4: MATCH
A5: EXP100229 | B5: EXP100228 | C5: E095 | D5: AX-535566578 | E5: 2026-01-17 | F5: 2026-01-17 | G5: STARBUCKS #4471 | H5: 5812 | I5: Meals | J5: 10.18 | K5: Corporate Amex | M5: Y | N5: Meals | O5: MATCH
A6: EXP100333 | B6: EXP100332 | C6: E037 | D6: ax710784387 | E6: 2026-01-23 | F6: 2026-01-24 | G6: YELLOW CAB CO | H6: 4121 | I6: Other | J6: 31.55 | K6: Corporate Amex | M6: Y | N6: Transportation | O6: MISMATCH
A7: EXP100340 | B7: EXP100339 | C7: E006 | E7: 2026-01-17 | F7: 2026-01-24 | G7: EVENTBRITE | H7: 7999 | I7: Events | J7: 615.37 | K7: Personal (Reimbursement) | L7: Forgot corporate card | M7: Y | N7: Events | O7: MATCH
A8: EXP100356 | B8: EXP100355 | C8: E067 | D8: AX 769497880 | E8: 2026-01-23 | F8: 2026-01-25 | G8: AMAZON MKTPLACE PMTS | H8: 5942 | I8: Office Supplies | J8: 466.63 | K8: Corporate Amex | M8: Y | N8: Office Supplies | O8: MATCH
A9: EXP100477 | B9: EXP100476 | C9: E197 | D9: AX704458560 | E9: 2026-01-29 | F9: 2026-01-30 | G9: SQ *THE CORNER BISTRO | H9: 5812 | I9: Meals | J9: 42.44 | K9: Corporate Amex | M9: Y | N9: Meals | O9: MATCH
A10: EXP100519 | B10: EXP100518 | C10: E049 | D10: AX476527762 | E10: 2026-01-27 | F10: 2026-02-02 | G10: YELLOW CAB CO | H10: 4121 | I10: Transportation | J10: 53.31 | K10: Corporate Amex | M10: N | N10: Transportation | O10: MATCH
A11: EXP100604 | B11: EXP100603 | C11: E010 | D11: AX237661685 | E11: 2026-02-06 | F11: 2026-02-06 | G11: UNITED AIRLINES 0162233 | H11: 4511 | I11: Travel | J11: 494.98 | K11: Corporate Amex | M11: Y | N11: Travel | O11: MATCH
A12: EXP100722 | B12: EXP100721 | C12: E025 | D12: AX 322996668 | E12: 2026-02-10 | F12: 2026-02-12 | G12: BRANDWATCH LTD | H12: 5734 | I12: Software | J12: 515.25 | K12: Corporate Amex | M12: Y | N12: Software | O12: MATCH
A13: EXP100774 | B13: EXP100773 | C13: E032 | D13: AX 422464517 | E13: 2026-02-10 | F13: 2026-02-15 | G13: YELLOW CAB CO | H13: 4121 | I13: Transportation | J13: 46.72 | K13: Corporate Amex | M13: Y | N13: Transportation | O13: MATCH
A14: EXP100813 | B14: EXP100811 | C14: E049 | D14: AX823523375 | E14: 2026-02-14 | F14: 2026-02-17 | G14: AMAZON MKTPLACE PMTS | H14: 5942 | I14: Office Supplies | J14: 146.13 | K14: Corporate Amex | M14: Y | N14: Office Supplies | O14: MATCH
A15: EXP100916 | B15: EXP100914 | C15: E057 | E15: 2026-02-15 | F15: 2026-02-21 | G15: UNITED AIRLINES 0162233 | H15: 4511 | I15: Travel | J15: 562.8 | K15: Personal (Reimbursement) | L15: International merchant - Amex not accepted | M15: N | N15: Travel | O15: MATCH
A16: EXP100942 | B16: EXP100941 | C16: E165 | D16: AX159066299 | E16: 2026-02-16 | F16: 2026-02-22 | G16: STAPLES #0231 | H16: 5943 | I16: Office Supplies | J16: 34.53 | K16: Corporate Amex | M16: Y | N16: Office Supplies | O16: MATCH
A17: EXP100955 | B17: EXP100954 | C17: E065 | D17: AX-827079423 | E17: 2026-02-15 | F17: 2026-02-23 | G17: AMC THEATRES 0021 | H17: 7832 | I17: Entertainment | J17: 33.98 | K17: Corporate Amex | M17: Y | N17: Entertainment | O17: MATCH
A18: EXP100985 | B18: EXP100984 | C18: E259 | E18: 2026-02-23 | F18: 2026-02-25 | G18: AMC THEATRES 0021 | H18: 7832 | I18: entertainment | J18: 37.95 | K18: Corporate Amex | M18: Y | N18: Entertainment | O18: MATCH
A19: EXP101122 | B19: EXP101121 | C19: E061 | E19: 2026-03-02 | F19: 2026-03-04 | G19: PANERA BREAD #0231 | H19: 5812 | I19: MEALS | J19: 15.65 | K19: Corporate Amex | M19: N | N19: Meals | O19: MATCH
A20: EXP101224 | B20: EXP101223 | C20: E080 | D20: AX181557087 | E20: 2026-03-05 | F20: 2026-03-10 | G20: STAPLES #0231 | H20: 5943 | I20: Office Supplies | J20: 137.02 | K20: Corporate Amex | M20: N | N20: Office Supplies | O20: MATCH
A21: EXP101279 | B21: EXP101278 | C21: E055 | E21: 2026-03-10 | F21: 2026-03-12 | G21: SQ *THE CORNER BISTRO | H21: 5812 | I21: Meals | J21: 66.82 | K21: Corporate Amex | M21: Y | N21: Meals | O21: MATCH
A22: EXP101475 | B22: EXP101474 | C22: E035 | D22: AX260127051 | E22: 2026-03-18 | F22: 2026-03-22 | G22: HYATT REGENCY BOS | H22: 7011 | I22: Lodging | J22: 307.79 | K22: Corporate Amex | M22: Y | N22: Lodging | O22: MATCH
A23: EXP101519 | B23: EXP101518 | C23: E043 | E23: 2026-03-20 | F23: 2026-03-24 | G23: CHIPOTLE 2214 | H23: 5812 | I23: Meals | J23: 10.41 | K23: Corporate Amex | M23: Y | N23: Meals | O23: MATCH
A24: EXP101566 | B24: EXP101565 | C24: E061 | D24: ax123682647 | E24: 2026-03-21 | F24: 2026-03-27 | G24: UBER TRIP HELP.UBER | H24: 4121 | I24: Transportation | J24: 64.16 | K24: Corporate Amex | M24: Y | N24: Transportation | O24: MATCH
A25: EXP101589 | B25: EXP101588 | C25: E034 | D25: AX-313246625 | E25: 2026-03-19 | F25: 2026-03-28 | G25: AMAZON MKTPLACE PMTS | H25: 5942 | I25: Office Supplies | J25: 62.09 | K25: Corporate Amex | M25: Y | N25: Office Supplies | O25: MATCH
A26: EXP101698 | B26: EXP101697 | C26: E095 | D26: AX-521400026 | E26: 2026-04-02 | F26: 2026-04-03 | G26: AMAZON MKTPLACE PMTS | H26: 5942 | I26: Office Supplies | J26: 454.2 | K26: Corporate Amex | M26: N | N26: Office Supplies | O26: MATCH
A27: EXP101722 | B27: EXP101721 | C27: E144 | D27: AX351870398 | E27: 2026-03-25 | F27: 2026-04-04 | G27: HYATT REGENCY BOS | H27: 7011 | I27: Lodging | J27: 309.59 | K27: Corporate Amex | M27: Y | N27: Lodging | O27: MATCH
A28: EXP101826 | B28: EXP101825 | C28: E041 | D28: AX489639112 | E28: 2026-04-06 | F28: 2026-04-10 | G28: TOTAL PARTY RENTAL | H28: 7999 | J28: 1393.86 | K28: Corporate Amex | M28: Y | N28: Events | O28: BLANK
A29: EXP101832 | B29: EXP101831 | C29: E023 | E29: 2026-04-10 | F29: 2026-04-10 | G29: SQ *JOES COFFEE | H29: 5812 | I29: Meals | J29: 6.09 | K29: Personal (Reimbursement) | L29: International merchant - Amex not accepted | M29: Y | N29: Meals | O29: MATCH
A30: EXP101847 | B30: EXP101846 | C30: E139 | D30: ax976324173 | E30: 2026-04-03 | F30: 2026-04-11 | G30: HYATT REGENCY BOS | H30: 7011 | I30: LODGING | J30: 478.77 | K30: Corporate Amex | M30: Y | N30: Lodging | O30: MATCH
A31: EXP101924 | B31: EXP101923 | C31: E003 | D31: AX185222306 | E31: 2026-04-06 | F31: 2026-04-14 | G31: SPROUT SOCIAL | H31: 5734 | I31: Software | J31: 155.38 | K31: Corporate Amex | M31: Y | N31: Software | O31: MATCH
A32: EXP102000 | B32: EXP101999 | C32: E025 | D32: ax319462600 | E32: 2026-04-17 | F32: 2026-04-18 | G32: CHIPOTLE 2214 | H32: 5812 | I32: Meals | J32: 14.89 | K32: Corporate Amex | M32: Y | N32: Meals | O32: MATCH
A33: EXP102137 | B33: EXP102135 | C33: E066 | D33: AX602260072 | E33: 2026-04-20 | F33: 2026-04-26 | G33: STAPLES #0231 | H33: 5943 | I33: Office Supplies | J33: 156.2 | K33: Corporate Amex | M33: Y | N33: Office Supplies | O33: MATCH
A34: EXP102153 | B34: EXP102152 | C34: E029 | D34: AX410842892 | E34: 2026-04-17 | F34: 2026-04-27 | G34: REGION CATERING CO | H34: 5811 | I34: Events | J34: 1042.03 | K34: Corporate Amex | M34: N | N34: Events | O34: MATCH
A35: EXP102166 | B35: EXP102165 | C35: E031 | D35: AX 965123709 | E35: 2026-04-23 | F35: 2026-04-27 | G35: HILTON GARDEN INN 2231 | H35: 7011 | I35: Lodging | J35: 256.11 | K35: Corporate Amex | M35: Y | N35: Lodging | O35: MATCH
A36: EXP102189 | B36: EXP102188 | C36: E018 | D36: AX-469682702 | E36: 2026-04-27 | F36: 2026-04-29 | G36: UNITED AIRLINES 0162233 | H36: 4511 | I36: Travel | J36: 540.29 | K36: Corporate Amex | M36: Y | N36: Travel | O36: MATCH
A37: EXP102365 | B37: EXP102364 | C37: E250 | E37: 2026-05-03 | F37: 2026-05-09 | G37: REGION CATERING CO | H37: 5811 | I37: Events | J37: 1695.37 | K37: Corporate Amex | M37: Y | N37: Events | O37: MATCH
A38: EXP102432 | B38: EXP102431 | C38: E118 | D38: ax713549337 | E38: 2026-05-11 | F38: 2026-05-13 | G38: TOTAL PARTY RENTAL | H38: 7999 | I38: Events | J38: 1037.81 | K38: Corporate Amex | M38: Y | N38: Events | O38: MATCH
A39: EXP102459 | B39: EXP102458 | C39: E044 | D39: AX873769634 | E39: 2026-05-14 | F39: 2026-05-14 | G39: HILTON GARDEN INN 2231 | H39: 7011 | J39: 296.21 | K39: Corporate Amex | M39: Y | N39: Lodging | O39: BLANK
A40: EXP102560 | B40: EXP102559 | C40: E012 | E40: 2026-05-12 | F40: 2026-05-20 | G40: SQ *THE CORNER BISTRO | H40: 5812 | I40: Meals | J40: 20.59 | K40: Personal (Reimbursement) | L40: International merchant - Amex not accepted | M40: Y | N40: Meals | O40: MATCH
...

Sheet Employees_Info
A1: EmpID | B1: Name | C1: Department | D1: Title | E1: ManagerID | F1: CardIssued
A2: E001 | B2: Layla Ivanova | C2: Sales & Marketing | D2: VP of Sales & Marketing | F2: Y
A3: E002 | B3: Nadia Petrova | C3: Sales & Marketing | D3: Sales Manager | E3: E001 | F3: Y
A4: E003 | B4: Olga Gupta | C4: Sales & Marketing | D4: Sales Manager | E4: E001 | F4: Y
A5: E004 | B5: Amir Bello | C5: Sales & Marketing | D5: Sales Manager | E5: E001 | F5: Y
A6: E005 | B6: Jennifer Wilson | C6: Sales & Marketing | D6: Senior Marketing Analyst | E6: E002 | F6: Y
A7: E006 | B7: Susan Andersson | C7: Sales & Marketing | D7: Senior Digital Media Analyst | E7: E002 | F7: Y
A8: E007 | B8: Omar Okafor | C8: Sales & Marketing | D8: Senior Marketing Analyst | E8: E002 | F8: Y
A9: E008 | B9: Yusuf Perez | C9: Sales & Marketing | D9: Senior Digital Media Analyst | E9: E003 | F9: Y
A10: E009 | B10: Priya Zhang | C10: Sales & Marketing | D10: Senior Marketing Analyst | E10: E003 | F10: Y
A11: E010 | B11: Isabella Nilsson | C11: Sales & Marketing | D11: Senior Digital Media Analyst | E11: E003 | F11: Y
A12: E011 | B12: Deshawn Brooks | C12: Sales & Marketing | D12: Senior Marketing Analyst | E12: E004 | F12: Y
A13: E012 | B13: Sven Delgado | C13: Sales & Marketing | D13: Senior Digital Media Analyst | E13: E004 | F13: Y
A14: E013 | B14: Amanda Flores | C14: Sales & Marketing | D14: Senior Marketing Analyst | E14: E004 | F14: Y
... A71: E070 | B71: Sanjay Robinson | C71: Sales & Marketing | D71: Sales Representative | E71: E007 | F71: Y
A72: E071 | B72: Sandra Malik | C72: Underwriting | D72: Director of Underwriting | F72: Y
A73: E072 | B73: Brandon Gupta | C73: Underwriting | D73: Underwriting Manager | E73: E071 | F73: Y
A74: E073 | B74: Denise Lewis | C74: Underwriting | D74: Underwriting Manager | E74: E071 | F74: Y
A75: E074 | B75: Anders Robinson | C75: Underwriting | D75: Senior Underwriter | E75: E072 | F75: Y
A76: E075 | B76: Nancy Harris | C76: Underwriting | D76: Senior Underwriter | E76: E072 | F76: Y
A77: E076 | B77: Joshua Taylor | C77: Underwriting | D77: Senior Underwriter | E77: E073 | F77: Y
A78: E077 | B78: Dmitri Moore | C78: Underwriting | D78: Senior Underwriter | E78: E073 | F78: Y
A79: E078 | B79: Andre Berg | C79: Underwriting | D79: Data Analyst | E79: E074 | F79: Y
A80: E079 | B80: Mateo Martinez | C80: Underwriting | D80: Underwriter | E80: E075 | F80: Y
A81: E080 | B81: Lisa Petrov | C81: Underwriting | D81: Underwriter | E81: E076 | F81: Y
A82: E081 | B82: David Chu | C82: Underwriting | D82: Data Analyst | E82: E077 | F82: Y
A83: E082 | B83: Isabella Ramirez | C83: Underwriting | D83: Underwriter | E83: E074 | F83: Y
A84: E083 | B84: Charles Ryan | C84: Underwriting | D84: Junior Underwriter | E84: E075 | F84: Y
... A116: E115 | B116: Sarah Lindqvist | C116: Underwriting | D116: Data Analyst | E116: E075 | F116: Y
A117: E116 | B117: Anjali Chu | C117: Claims | D117: Director of Claims | F117: Y
A118: E117 | B118: Wei Siddiqui | C118: Claims | D118: Claims Manager | E118: E116 | F118: Y
A119: E118 | B119: Brandon Khan | C119: Claims | D119: Claims Manager | E119: E116 | F119: Y
A120: E119 | B120: Tanya Clark | C120: Claims | D120: Senior Claims Analyst | E120: E117 | F120: Y
A121: E120 | B121: Elena Thompson | C121: Claims | D121: Senior Claims Analyst | E121: E117 | F121: Y
A122: E121 | B122: Nadia Gupta | C122: Claims | D122: Senior Claims Analyst | E122: E118 | F122: Y
A123: E122 | B123: Tanya Nilsson | C123: Claims | D123: Senior Claims Analyst | E123: E118 | F123: Y
A124: E123 | B124: Tanya Chen | C124: Claims | D124: Junior Claims Analyst | E124: E119 | F124: Y
A125: E124 | B125: Jeffrey Brown | C125: Claims | D125: Claims Analyst | E125: E120 | F125: Y
A126: E125 | B126: Miguel Cohen | C126: Claims | D126: Claims Analyst | E126: E121 | F126: Y
A127: E126 | B127: Hiroshi Johnson | C127: Claims | D127: Claims Analyst | E127: E122 | F127: Y
...

Sheet MCC_Lookup
A1: MCC | B1: Category
A2: 5812 | B2: Meals
A3: 4511 | B3: Travel
A4: 7011 | B4: Lodging
A5: 4121 | B5: Transportation
A6: 5943 | B6: Office Supplies
A7: 5942 | B7: Office Supplies
A8: 5734 | B8: Software
A9: 7832 | B9: Entertainment
A10: 7997 | B10: Entertainment
A11: 7999 | B11: Events
A12: 5811 | B12: Events

Sheet Data_Cleaning_Log
A1: Check | B1: Method | C1: Result | D1: Why It Matters
A2: Date format | B2: Checked ExpenseDate and SubmissionDate and converted the mixed date formats into actual Excel dates. | C2: All 3,634 rows were verified as valid dates. | D2: This makes it possible to sort expenses by date and calculate things like submission delays.
A3: Amount format | B3: Removed $ signs and commas and converted the amounts to numbers. | C3: 324 rows needed to be fixed. All amounts are now numeric. | D3: Numeric values are needed for calculations such as total spending, averages, and budget comparisons.
A4: Category verification | B4: Compared the employee's category with the category from the MCC lookup table. | C4: Match: 90.46% · Mismatch: 3.77% · Blank: 5.78% | D4: This helps identify expenses where the employee-entered category does not match the transaction category.
A5: Duplicate detection | B5: Checked for transactions with the same employee, merchant, and amount. Kept the first record and moved the duplicate records to a separate sheet. | C5: 54 duplicate rows were removed from the original 3,688 transactions. | D5: Removing duplicates prevents the same expense from being counted more than once in the analysis.
